<?xml version="1.0"?>
<robot name="three_wheel_bot"
       xmlns:xacro="http://ros.org/wiki/xacro">

  <!-- parameters -->
  <xacro:property name="wheel_radius" value="0.05"/>
  <xacro:property name="wheel_base"   value="0.3"/>

  <!-- Base link -->
  <link name="base_link">
    <inertial>
      <mass value="5.0"/>
      <origin xyz="0 0 0" rpy="0 0 0"/>
      <inertia ixx="0.1" iyy="0.1" izz="0.1"
               ixy="0" ixz="0" iyz="0"/>
    </inertial>
    <visual>
      <origin xyz="0 0 0" rpy="0 0 0"/>
      <geometry>
        <box size="0.4 0.3 0.1"/>
      </geometry>
      <material name="Grey"/>
    </visual>
    <collision>
      <origin xyz="0 0 0" rpy="0 0 0"/>
      <geometry>
        <box size="0.4 0.3 0.1"/>
      </geometry>
    </collision>
  </link>

  <!-- Wheel macro -->
  <xacro:macro name="wheel" params="name x y">
    <link name="${name}_wheel_link">
      <inertial>
        <mass value="0.1"/>
        <origin xyz="0 0 0" rpy="0 0 0"/>
        <inertia ixx="0.001" iyy="0.001" izz="0.001" ixy="0" ixz="0" iyz="0"/>
      </inertial>
      <visual>
        <origin xyz="0 0 0" rpy="1.5708 0 0"/>
        <geometry>
          <cylinder radius="${wheel_radius}" length="0.02"/>
        </geometry>
        <material name="Black">
          <color rgba="0 0 0 1"/>
        </material>
      </visual>
      <collision>
        <origin xyz="0 0 0" rpy="1.5708 0 0"/>
        <geometry>
          <cylinder radius="${wheel_radius}" length="0.02"/>
        </geometry>
      </collision>
    </link>

    <joint name="${name}_wheel_joint" type="continuous">
      <parent link="base_link"/>
      <child  link="${name}_wheel_link"/>
      <origin xyz="${x} ${y} -0.05" rpy="0 0 0"/>
      <axis  xyz="0 1 0"/>
    </joint>
  </xacro:macro>

  <!-- Instantiate the three wheels -->
  <xacro:wheel name="left"  x="-0.1"              y="${wheel_base/2}"/>
  <xacro:wheel name="right" x="-0.1"              y="${-wheel_base/2}"/>
  <xacro:wheel name="back"  x="${wheel_base-0.15}" y="0"/>

  <!-- Gazebo diff_drive plugin -->
  <gazebo>
    <plugin name="diff_drive" filename="libgazebo_ros_diff_drive.so">
      <ros>
        <namespace>/</namespace>
      </ros>
      <cmdVelTopic>/cmd_vel</cmdVelTopic>
      <odometryTopic>/odom</odometryTopic>
      <odometryTopic>odom</odometryTopic>
      <robotBaseFrame>base_link</robotBaseFrame>
      <leftJoint>left_wheel_joint</leftJoint>
      <rightJoint>right_wheel_joint</rightJoint>
      <updateRate>50</updateRate>
      <wheelSeparation>${wheel_base*2}</wheelSeparation>
      <wheelRadius>${wheel_radius}</wheelRadius>
    </plugin>
  </gazebo>

</robot>

